Workbook

Sheet NEW POOL
A1: 2025 PRICING MASTER - September
A3: CUSTOMER NAME: | B3: Bishop
A4: CITY: | B4: Indian Land
A5: Silt Fence: | B5: 1 | C5: "1" if Silt Fence is required
A7: Perimeter: | B7: 104 | C7: LNFT | D7: Max Width: | E7: 16 | F7: FT | J7: =IF(B$21+B$22+B$23>0,1,0) -> 0
A8: Surface Area: | B8: 576 | C8: SQFT | D8: Max Length: | E8: 36 | F8: FT | G8: `
A9: Shallow Depth: | B9: 3.5 | C9: FT | D9: Decking: | E9: 834 | F9: SQFT | G9: 817 | H9: 713
A10: End Depth: | B10: 7 | C10: FT | D10: Travel: | E10: 0 | F10: MILES
A11: Total Step & Bench: | B11: 70 | C11: LNFT | D11: Pool to Street: | E11: 0 | F11: ( 1 if 251 to 300, 2 if 300 to 350)
A12: Tanning Shelf: | B12: 0 | C12: 1 for Yes, 0 for No
D13: Approx. Gallons: | E13: =_xlfn.CEILING.MATH(((B8*((B9+B10)/2))*7.6),10)-(B12*850) -> 22990 | F13: DO NOT ADJUST GALLONS HERE!
A14: Spa Length: | B14: 0
A15: Spa Width: | B15: 0
A16: Spa Shape: | B16: 0 | C16: ( 1 for Round, 2 for Square )
A17: Spa Perimeter: | B17: =ROUNDUP(IF(B16=1,(B14*3.14),(B14*2+B15*2)),0) -> 0 | C17: DO NOT CHANGE HERE!
A18: Raised Spa?: | B18: 0 | C18: ( 1 for Yes, 0 for No) | E18: (Raised Spa = +18")
A19: Raised Spa Facing: | B19: 0 | C19: ( 1=Tile / 2=Ledgstone / 3=Stacked Stone)
A21: Fiberglass - Small | B21: =IF(A21="Fiberglass - Small",0,1) -> 0
A22: Fiberglass - Medium | B22: 0
A23: Fiberglass - Large | B23: =IF(A23="Fiberglass - Large",0,1) -> 0
A24: Standard Finish | B24: 0
A25: No Spa | B25: =IF(A25="No Spa",0,1) -> 0
A26: Add Spillover | B26: 0
A27: No Tanning | B27: =IF(A27="No Tanning",0,1) -> 0
A28: No Crane | B28: =IF(A28="No Crane",0,1) -> 0
A30: EXCAVATION
B31: LNFT | C31: FACING
A32: 6" RBB: | B32: 0 | C32: 0 | D32: ( 1=Tile / 2=Panel Ledge / 3=Stacked Stone)
A33: 12" RBB: | B33: 0 | C33: 0
A34: 18" RBB: | B34: 0 | C34: 0
A35: 24" RBB: | B35: 0 | C35: 0
A36: 30" RBB: | B36: 0 | C36: 0
A37: 36" RBB: | B37: 0 | C37: 0
A38: Total SQFT of RBB: | B38: =SHOT!L10 -> 0 | C38: DO NOT CHANGE HERE!
C39: FACING
A40: # of Columns | B40: 0 | C40: 0 | D40: =D32 -> ( 1=Tile / 2=Panel Ledge / 3=Stacked Stone)
A41: Coumn Width: | B41: 0 | C41: FT
A42: Column Depth: | B42: 0 | C42: FT
A43: Column Height: | B43: 0 | C43: FT
A45: Add'l Site Prep: | B45: 0 | C45: Hours
...

Sheet CUSTOM
C1: Material | D1: Labor | E1: Total
C2: Cost | D2: Cost | E2: Cost | G2: Retail
A3: Parged Concrete | C3: 0 | D3: 0 | E3: =C3+D3 -> 0 | F3: 0.7 | G3: =E3/F3 -> 0
A5: Oversized coping | C5: 824 | D5: 0 | E5: =C5+D5 -> 824 | F5: 0.7 | G5: =E5/F5 -> 1177.1429
A7: handrail | C7: 1028 | D7: 0 | E7: =C7+D7 -> 1028 | F7: 0.7 | G7: =E7/F7 -> 1468.5714 | H7: 763+80+185
A9: No Custom Feature | C9: 0 | D9: 0 | E9: =C9+D9 -> 0 | F9: 0.7 | G9: =E9/F9 -> 0
A11: No Custom Feature | C11: 0 | D11: 0 | E11: =C11+D11 -> 0 | F11: 0.7 | G11: =E11/F11 -> 0
A13: No Custom Feature | C13: 0 | D13: 0 | E13: =C13+D13 -> 0 | F13: 0.7 | G13: =E13/F13 -> 0
A15: No Custom Feature | C15: 0 | D15: 0 | E15: =C15+D15 -> 0 | F15: 0.7 | G15: =E15/F15 -> 0
A17: No Custom Feature | C17: 0 | D17: 0 | E17: =C17+D17 -> 0 | F17: 0.7 | G17: =E17/F17 -> 0

Sheet PROPOSAL
B1: 2025 | F1: Proposal & Specifications
F2: Prepared by:
F4: John Piotrowski
F5: 980-392-7944
B6: a passion for splashin' | F6: jpiotrowski@ppas.com
A7: PREPARED FOR: | B7: ='NEW POOL'!B3 -> Bishop | F7: =TODAY() -> 45959
B8: ='NEW POOL'!B4 -> Indian Land
A10: Dimensions | B10: Width | C10: Length | D10: Shallow | E10: Deep | F10: Premier Advantage
A11: Pool Dimensions (Feet) | B11: ='NEW POOL'!E7 -> 16 | C11: ='NEW POOL'!E8 -> 36 | D11: ='NEW POOL'!B9 -> 3.5 | E11: ='NEW POOL'!B10 -> 7
A12: Spa Dimensions (Feet) | B12: ='NEW POOL'!B15 -> 0 | C12: ='NEW POOL'!B14 -> 0 | D12: =IF(B12>0,3,0) -> 0 | E12: 0 | F12: =IF(C12=0,"No Spa","Split Bench for Customized Therapy") -> No Spa
A13: =IF(I43=1,"Shell:","Notes:") -> Notes: | B13: =IF('NEW POOL'!A21="Fiberglass - Small","",'NEW POOL'!A21)
B14: =IF('NEW POOL'!A22="Fiberglass - Medium","",'NEW POOL'!A22)
B15: =IF('NEW POOL'!A23="Fiberglass - Large","",'NEW POOL'!A23)
A17: Steps & Benches | F17: Premier Advantage
A18: One set of shallow-end access steps
A19: Deep-end loveseat bench | F19: For safety and relaxing
A20: Notes:
A23: Plans, Permits & Insurance | F23: Premier Advantage
A24: Detailed construction plans in advance for approval prior to excavation | F24: Ensures clear understanding of project details
A25: Engineered structural plans | F25: Certificates available upon request
A26: All required building permits
A27: Underground services alert called prior to excavation
A28: All work and vehicles are covered by commercial liability and auto insurance
A29: All employees are covered by Workers Compensation Insurance
A30: Taxes on all materials and equipment included in contract price
A31: Lien releases are available throughout construction
A32: Premier is licensed and bonded in accordance with State Contractors Board Regulations
A33: Notes:
A36: Excavation | F36: Premier Advantage
A37: Pool layout prior to excavation | F37: Pool is painted on ground for visual approval by homeowner
A38: Pool hand contoured | F38: Hand trimming assures uniform wall and floor thickness with proper cove radius
A40: Notes:
A43: Steel | F43: Premier Advantage | I43: =I76 -> 0
A44: =IF(I43=1,"Fiberglass Shell - No Steel","4 bar bond beam with ½ inch steel; 3/8 inch rebar on 10 inch centers through pool") -> 4 bar bond beam with ½ inch steel; 3/8 inch rebar on 10 inch centers through pool | F44: =IF(I43=1,"","Our bond beam and wall steel schedules are beyond code for protection against expansive soils") -> Our bond beam and wall steel schedules are beyond code for protection against expansive soils
A45: =IF(I43=1,"","10 inch on center in transition slope by 20 feet length") -> 10 inch on center in transition slope by 20 feet length | F45: =IF(I43=1,"","Strongest steel schedule in the industry!") -> Strongest steel schedule in the industry!
A46: 8" on center in the deep end and coves
A48: Notes:
A51: Plumbing | F51: Premier Advantage
A52: 2 ½ inch suction line | F52: Premier Stealth Series pump
A53: 2 ½ inch suction line for all pump motors larger than 1.0 HP | F53: Premier High-Performance circulation pump
...

Sheet COST - NEW
A2: PLANS & ENGINEERING
A3: =PLANS!A4 -> Pool Only: | B3: =PLANS!B4 -> 410 | C3: =PLANS!C4 -> 1 | D3: =PLANS!D4 -> 410
A4: =PLANS!A5 -> Spa: | B4: =PLANS!B5 -> 80 | C4: =PLANS!C5 -> 0 | D4: =PLANS!D5 -> 0
A5: =PLANS!A6 -> Waterfall: | B5: =PLANS!B6 -> 15 | C5: =PLANS!C6 -> 0 | D5: =PLANS!D6 -> 0
A6: =PLANS!A7 -> Waterfeature: | B6: =PLANS!B7 -> 10 | C6: =PLANS!C7 -> 0 | D6: =PLANS!D7 -> 0
A7: =PLANS!A8 -> Soil Sample / Engineer: | B7: =PLANS!B8 -> 750 | C7: =PLANS!C8 -> 1 | D7: =PLANS!D8 -> 750
A9: PLANS & ENGINEERING TOTAL | D9: =SUM(D3:D8) -> 1160
A11: LAYOUT
A12: Pool Only | B12: 50 | C12: 1 | D12: =B12*C12 -> 50
A13: Spa | B13: 15 | C13: =EXC!C27 -> 0 | D13: =B13*C13 -> 0
A14: Silt Fencing, Etc. | B14: 500 | C14: ='NEW POOL'!B5 -> 1 | D14: =B14*C14 -> 500
A16: LAYOUT TOTAL | D16: =SUM(D12:D15) -> 550
A18: PERMIT
A19: Pool Only: | B19: 850 | C19: 1 | D19: =B19*C19 -> 850
A20: Spa: | B20: 150 | C20: =EXC!C27 -> 0 | D20: =B20*C20 -> 0
A21: Permit Runner: | B21: 75 | C21: 1 | D21: =B21*C21 -> 75
A23: PERMIT TOTAL | D23: =SUM(D19:D22) -> 925
A25: EXCAVATION
A26: Base Excavation: | B26: =EXC!G5 -> 576 | D26: =EXC!D18 -> 2700
A27: Over 1,000 SQFT: | B27: =EXC!B17 -> 4 | C27: =EXC!C17 -> 0 | D27: =EXC!D17 -> 0
A28: =EXC!A20 -> Add'l 6" Depth: | B28: =EXC!B20 -> 90 | C28: =EXC!C20 -> 0 | D28: =EXC!D20 -> 0
A29: =EXC!A21 -> 6" RBB: | B29: =EXC!B21 -> 5 | C29: =EXC!C21 -> 0 | D29: =EXC!D21 -> 0
A30: =EXC!A22 -> 12" RBB: | B30: =EXC!B22 -> 6.5 | C30: =EXC!C22 -> 0 | D30: =EXC!D22 -> 0
A31: =EXC!A23 -> 18" RBB: | B31: =EXC!B23 -> 7.5 | C31: =EXC!C23 -> 0 | D31: =EXC!D23 -> 0
A32: =EXC!A24 -> 24" RBB: | B32: =EXC!B24 -> 8.5 | C32: =EXC!C24 -> 0 | D32: =EXC!D24 -> 0
A33: =EXC!A25 -> 30" RBB" | B33: =EXC!B25 -> 9 | C33: =EXC!C25 -> 0 | D33: =EXC!D25 -> 0
A34: =EXC!A26 -> 36" RBB: | B34: =EXC!B26 -> 10 | C34: =EXC!C26 -> 0 | D34: =EXC!D26 -> 0
A35: =EXC!A27 -> Base Spa: | B35: =EXC!B27 -> 200 | C35: =EXC!C27 -> 0 | D35: =EXC!D27 -> 0
A36: =EXC!A28 -> Raise Spa: | B36: =EXC!B28 -> 350 | C36: =EXC!C28 -> 0 | D36: =EXC!D28 -> 0
A37: =EXC!A29 -> Site Prep: | B37: =EXC!B29 -> 200 | C37: =EXC!C29 -> 0 | D37: =EXC!D29 -> 0
A38: =EXC!A30 -> Backfill: | B38: =EXC!B30 -> 600 | C38: =EXC!C30 -> 1 | D38: =EXC!D30 -> 600
A39: =EXC!A31 -> Gravel: | B39: =EXC!B31 -> 1 | C39: =EXC!C31 -> 2.75 | D39: =EXC!D31 -> 1584
A40: =EXC!A32 -> Dirt Haul: | B40: =EXC!B32 -> 18 | C40: =ROUNDUP(EXC!C32,0) -> 180 | D40: =ROUNDUP(EXC!D32,0) -> 3230
A41: =EXC!A33 -> Cover Box: | B41: =EXC!B33 -> 450 | C41: =EXC!C33 -> 0 | D41: =EXC!D33 -> 0
A42: =EXC!A34 -> Travel: | B42: =EXC!B34 -> 7 | C42: =EXC!C34 -> 0 | D42: =EXC!D34 -> 0
A43: =EXC!A35 -> Misc: | B43: =EXC!B35 -> 75 | C43: =EXC!C35 -> 1 | D43: =EXC!D35 -> 75 | E43: Discount
A44: PAP Discount: | D44: =F44*-E44 -> -818.9 | E44: 0.1 | F44: =SUM(D26:D43) -> 8189
A45: EXCAVATION TOTAL: | D45: =IF('NEW POOL'!B21+'NEW POOL'!B22+'NEW POOL'!B23>0,D40+('NEW POOL'!B47*D43),SUM(D26:D44)) -> 7370.1
A47: PLUMBING
A48: =PLUM!A4 -> Short Stub | B48: =PLUM!B4 -> 550 | C48: =PLUM!C4 -> 1 | D48: =PLUM!D4 -> 550
...

Sheet SUMMARY - NEW
A1: JOB COST SUMMARY
A3: CUSTOMER NAME: | B3: ='NEW POOL'!B3 -> Bishop
A5: PLANS & ENGINEERING TOTAL | D5: ='COST - NEW'!D9 -> 1160
A7: LAYOUT TOTAL | D7: ='COST - NEW'!D16 -> 550
A9: PERMIT TOTAL | D9: ='COST - NEW'!D23 -> 925
A11: EXCAVATION TOTAL: | D11: ='COST - NEW'!D45 -> 7370.1
A13: PLUMBING TOTAL: | D13: ='COST - NEW'!D71 -> 4347.25
A15: GAS TOTAL: | D15: ='COST - NEW'!D77 -> 0
A17: STEEL TOTAL: | D17: =OTHER!D17 -> 3564
A19: ELECTRICAL TOTAL: | D19: ='COST - NEW'!D121 -> 2385
A21: SHOTCRETE LABOR TOTAL: | D21: =OTHER!D21 -> 3690
A23: SHOTCRETE MATERIAL TOTAL: | D23: =OTHER!D23 -> 11393.168
A25: TILE LABOR TOTAL: | D25: =OTHER!D25 -> 1040
A27: TILE MATERIAL TOTAL: | D27: =OTHER!D27 -> 782.6
A29: COPING / DECKING LABOR TOTAL: | D29: ='COST - NEW'!D204 -> 7685.04
A31: COPING / DECKING MATERIAL TOTAL: | D31: ='COST - NEW'!D206 -> 4532.4118
A33: STONE / ROCKWORK LABOR TOTAL: | D33: ='COST - NEW'!D225 -> 0
A35: STONE / ROCKWORK MATERIAL TOTAL: | D35: ='COST - NEW'!D227 -> 0
A37: DRAINAGE: | D37: =MISC!D18 -> 0
A39: EQUIPMENT ORDERED TOTAL: | D39: ='COST - NEW'!D261 -> 8132.267
A41: EQUIPMENT SET TOTAL: | D41: ='COST - NEW'!D272 -> 875
A43: CLEAN-UP TOTAL: | D43: ='COST - NEW'!D282 -> 1438
A45: INTERIOR FINISH TOTAL: | D45: =OTHER!D43 -> 8577.55
A47: WATER TRUCK TOTAL: | D47: =INT!D28 -> 1715
A49: FIBERGLASS SHELL TOTAL: | D49: =OTHER!D45 -> 0
A51: FIBERGLASS INSTALL TOTAL: | D51: =OTHER!D47 -> 150
A53: START-UP / ORIENTATION TOTAL: | D53: ='COST - NEW'!D330 -> 1000
A55: =CUSTOM!A3 -> Parged Concrete | D55: ='COST - NEW'!D333 -> 0
A57: =CUSTOM!A5 -> Oversized coping | D57: ='COST - NEW'!D334 -> 824
A59: =CUSTOM!A7 -> handrail | D59: ='COST - NEW'!D335 -> 1028
A61: =CUSTOM!A9 -> No Custom Feature | D61: ='COST - NEW'!D336 -> 0
A63: =CUSTOM!A11 -> No Custom Feature | D63: ='COST - NEW'!D337 -> 0
A65: =CUSTOM!A13 -> No Custom Feature | D65: ='COST - NEW'!D338 -> 0
A67: =CUSTOM!A15 -> No Custom Feature | D67: ='COST - NEW'!D339 -> 0
A69: =CUSTOM!A17 -> No Custom Feature | D69: ='COST - NEW'!D340 -> 0
A71: TOTAL COST: | D71: =SUM(D5:D70) -> 73164.386

Sheet OTHER
A1: JOB COST SUMMARY
A3: CUSTOMER NAME: | B3: ='NEW POOL'!B3 -> Bishop | F3: Pool Only | G3: Pool / Spa | M3: 0.7
F4: Base | G4: Base | I4: As-Designed | K4: Difference | M4: Retail Difference
A5: PLANS & ENGINEERING TOTAL | D5: ='COST - NEW'!D9 -> 1160 | F5: 275 | G5: 315 | I5: =D5 -> 1160 | K5: =IF(EXC!$C$27=0,OTHER!I5-OTHER!F5,OTHER!I5-OTHER!G5) -> 885 | M5: =K5/$M$3 -> 1264.2857
A7: LAYOUT TOTAL | D7: ='COST - NEW'!D16 -> 550 | F7: 65 | G7: 65 | I7: =D7 -> 550 | K7: =IF(EXC!$C$27=0,OTHER!I7-OTHER!F7,OTHER!I7-OTHER!G7) -> 485 | M7: =K7/$M$3 -> 692.85714
A9: PERMIT TOTAL | D9: ='COST - NEW'!D23 -> 925 | F9: 925 | G9: 1075 | I9: =D9 -> 925 | K9: =IF(EXC!$C$27=0,OTHER!I9-OTHER!F9,OTHER!I9-OTHER!G9) -> 0 | M9: =K9/$M$3 -> 0
A11: EXCAVATION TOTAL: | D11: ='COST - NEW'!D45 -> 7370.1 | F11: 3650 | G11: 4000 | I11: =D11 -> 7370.1 | K11: =IF(EXC!$C$27=0,OTHER!I11-OTHER!F11,OTHER!I11-OTHER!G11) -> 3720.1 | M11: =K11/$M$3 -> 5314.4286
A13: PLUMBING TOTAL: | D13: ='COST - NEW'!D71 -> 4347.25 | F13: 1833.5 | G13: 3058 | I13: =D13 -> 4347.25 | K13: =IF(EXC!$C$27=0,OTHER!I13-OTHER!F13,OTHER!I13-OTHER!G13) -> 2513.75 | M13: =CEILING(K13/$M$3,10) -> 3600
A15: GAS TOTAL: | D15: ='COST - NEW'!D77 -> 0 | F15: 0 | G15: 0 | I15: =D15 -> 0 | K15: =IF(EXC!$C$27=0,OTHER!I15-OTHER!F15,OTHER!I15-OTHER!G15) -> 0 | M15: =CEILING(K15/$M$3,10) -> 0
A17: STEEL TOTAL: | D17: =IF('NEW POOL'!$B$21+'NEW POOL'!$B$22+'NEW POOL'!$B$23>0,0,'COST - NEW'!D104) -> 3564 | F17: 2950 | G17: 3450 | I17: =D17 -> 3564 | K17: =IF(EXC!$C$27=0,OTHER!I17-OTHER!F17,OTHER!I17-OTHER!G17) -> 614 | M17: =K17/$M$3 -> 877.14286
A19: ELECTRICAL TOTAL: | D19: ='COST - NEW'!D121 -> 2385 | F19: 2010 | G19: 2135 | I19: =D19 -> 2385 | K19: =IF(EXC!$C$27=0,OTHER!I19-OTHER!F19,OTHER!I19-OTHER!G19) -> 375 | M19: =K19/$M$3 -> 535.71429
A21: SHOTCRETE LABOR TOTAL: | D21: =IF('NEW POOL'!$B$21+'NEW POOL'!$B$22+'NEW POOL'!$B$23>0,0,'COST - NEW'!D145) -> 3690 | F21: 2880 | G21: 3400 | I21: =D21 -> 3690 | K21: =IF(EXC!$C$27=0,OTHER!I21-OTHER!F21,OTHER!I21-OTHER!G21) -> 810 | M21: =K21/$M$3 -> 1157.1429
A23: SHOTCRETE MATERIAL TOTAL: | D23: =IF('NEW POOL'!$B$21+'NEW POOL'!$B$22+'NEW POOL'!$B$23>0,0,'COST - NEW'!D147) -> 11393.168 | F23: 6992.7 | G23: 8113.46 | I23: =D23 -> 11393.168 | K23: =IF(EXC!$C$27=0,OTHER!I23-OTHER!F23,OTHER!I23-OTHER!G23) -> 4400.4675 | M23: =K23/$M$3 -> 6286.3821
A25: TILE LABOR TOTAL: | D25: =IF('NEW POOL'!$B$21+'NEW POOL'!$B$22+'NEW POOL'!$B$23>0,0,'COST - NEW'!D173) -> 1040 | F25: 830 | G25: 1180 | I25: =D25 -> 1040 | K25: =IF(EXC!$C$27=0,OTHER!I25-OTHER!F25,OTHER!I25-OTHER!G25) -> 210 | M25: =K25/$M$3 -> 300
A27: TILE MATERIAL TOTAL: | D27: =IF('NEW POOL'!$B$21+'NEW POOL'!$B$22+'NEW POOL'!$B$23>0,0,'COST - NEW'!D175) -> 782.6 | F27: 540 | G27: 752.8 | I27: =D27 -> 782.6 | K27: =IF(EXC!$C$27=0,OTHER!I27-OTHER!F27,OTHER!I27-OTHER!G27) -> 242.6 | M27: =K27/$M$3 -> 346.57143
A29: COPING / DECKING LABOR TOTAL: | D29: ='COST - NEW'!D204 -> 7685.04 | F29: 0 | G29: 0 | I29: =D29 -> 7685.04 | K29: =IF(EXC!$C$27=0,OTHER!I29-OTHER!F29,OTHER!I29-OTHER!G29) -> 7685.04 | L29: 0.745 | M29: =CEILING(K29/L29,10) -> 10320
A31: COPING / DECKING MATERIAL TOTAL: | D31: ='COST - NEW'!D206 -> 4532.4118 | F31: 0 | G31: 0 | I31: =D31 -> 4532.4118 | K31: =IF(EXC!$C$27=0,OTHER!I31-OTHER!F31,OTHER!I31-OTHER!G31) -> 4532.4118 | L31: 0.745 | M31: =CEILING(K31/L31,10) -> 6090
A33: STONE / ROCKWORK LABOR TOTAL: | D33: ='COST - NEW'!D225 -> 0 | F33: 0 | G33: 0 | I33: =D33 -> 0 | K33: =IF(EXC!$C$27=0,OTHER!I33-OTHER!F33,OTHER!I33-OTHER!G33) -> 0 | M33: =CEILING(K33/$M$3,40) -> 0
A35: STONE / ROCKWORK MATERIAL TOTAL: | D35: ='COST - NEW'!D227 -> 0 | F35: 0 | G35: 0 | I35: =D35 -> 0 | K35: =IF(EXC!$C$27=0,OTHER!I35-OTHER!F35,OTHER!I35-OTHER!G35) -> 0 | M35: =CEILING(K35/$M$3,40) -> 0
A37: EQUIPMENT ORDERED TOTAL: | D37: ='COST - NEW'!D261 -> 8132.267 | F37: 3504.25 | G37: 3504.25 | I37: =D37 -> 8132.267 | K37: =IF(EXC!$C$27=0,OTHER!I37-OTHER!F37,OTHER!I37-OTHER!G37) -> 4628.017 | M37: =K37/$M$3 -> 6611.4529
A39: EQUIPMENT SET TOTAL: | D39: ='COST - NEW'!D272 -> 875 | F39: 550 | G39: 550 | I39: =D39 -> 875 | K39: =IF(EXC!$C$27=0,OTHER!I39-OTHER!F39,OTHER!I39-OTHER!G39) -> 325 | M39: =K39/$M$3 -> 464.28571
A41: CLEAN-UP TOTAL: | D41: ='COST - NEW'!D282 -> 1438 | F41: 700 | G41: 800 | I41: =D41 -> 1438 | K41: =IF(EXC!$C$27=0,OTHER!I41-OTHER!F41,OTHER!I41-OTHER!G41) -> 738 | M41: =K41/$M$3 -> 1054.2857
A43: INTERIOR FINISH TOTAL: | D43: =IF('NEW POOL'!$B$21+'NEW POOL'!$B$22+'NEW POOL'!$B$23>0,0,'COST - NEW'!D295) -> 8577.55 | F43: 4278 | G43: 5340.96 | I43: =D43 -> 8577.55 | K43: =IF(EXC!$C$27=0,OTHER!I43-OTHER!F43,OTHER!I43-OTHER!G43) -> 4299.55 | M43: =IF(D43=0,0,CEILING(K43/$M$3,320)) -> 6400
A45: FIBERGLASS SHELL TOTAL: | D45: ='COST - NEW'!D315 -> 0
A47: FIBERGLASS INSTALL TOTAL: | D47: =SUM(FIBER!G66:G78) -> 150
A49: START-UP / ORIENTATION TOTAL: | D49: ='COST - NEW'!D330 -> 1000 | F49: 500 | G49: 500 | I49: =D49 -> 1000 | K49: =IF(EXC!$C$27=0,OTHER!I49-OTHER!F49,OTHER!I49-OTHER!G49) -> 500 | M49: =K49/$M$3 -> 714.28571
A51: ='SUMMARY - NEW'!A55 -> Parged Concrete | D51: ='SUMMARY - NEW'!D55 -> 0
A53: ='SUMMARY - NEW'!A57 -> Oversized coping | D53: ='SUMMARY - NEW'!D57 -> 824
A55: ='SUMMARY - NEW'!A59 -> handrail | D55: ='SUMMARY - NEW'!D59 -> 1028
A57: ='SUMMARY - NEW'!A61 -> No Custom Feature | D57: ='SUMMARY - NEW'!D61 -> 0
A59: TOTAL COST: | D59: =SUM(D5:D58) -> 71449.386 | F59: =SUM(F5:F50) -> 32483.45 | G59: =SUM(G5:G50) -> 38239.47 | I59: =SUM(I5:I50) -> 69447.386 | K59: =I59-F59 -> 36963.936 | M59: =K59/$M$3 -> 52805.623
G60: =G59-F59 -> 5756.02 | H60: 0.71
G61: =G60/H60 -> 8107.0704
F63: Spa Base: | G63: 14950
A66: Additional Size: | F66: Add'l Depth | G66: Retail
A67: Perimeter: | B67: 125 | C67: =IF('NEW POOL'!B7>80,'NEW POOL'!B7-80,0) -> 24 | D67: =B67*C67 -> 3000 | F67: 6 | G67: 1050 | H67: =IF('NEW POOL'!$B$10=6,1,0) -> 0 | I67: =G67*H67 -> 0
A68: Surface Area: | B68: 12 | C68: =IF('NEW POOL'!B8>400,'NEW POOL'!B8-400,0) -> 176 | D68: =B68*C68 -> 2112 | F68: 7 | G68: 1390 | H68: =IF('NEW POOL'!$B$10=7,1,0) -> 1 | I68: =G68*H68 -> 1390
A69: Additional Depth: | C69: =SUM(H67:H70) -> 1 | D69: =I72 -> 1390 | F69: 8 | G69: 2750 | H69: =IF('NEW POOL'!$B$10=8,1,0) -> 0 | I69: =G69*H69 -> 0
F70: 9 | G70: 3880 | H70: =IF('NEW POOL'!$B$10=9,1,0) -> 0 | I70: =G70*H70 -> 0
I72: =SUM(I67:I70) -> 1390

Sheet BILLING
F3: CUSTOMER: | G3: ='NEW POOL'!B3 -> Bishop
F5: CITY: | G5: ='NEW POOL'!B4 -> Indian Land
A9: IN-HOUSE BILLING
A12: Permit Runner | G12: ='COST - NEW'!D21 -> 75
A15: Layout | G15: 65
A18: Waterproofing | G18: =CEILING('COST - NEW'!D293,1) -> 0

Sheet PLANS
A1: MAY 2020
A3: PLANS & ENGINEERING
A4: Pool Only: | B4: 410 | C4: 1 | D4: =B4*C4 -> 410
A5: Spa: | B5: 80 | C5: =EXC!C27 -> 0 | D5: =B5*C5 -> 0
A6: Waterfall: | B6: 15 | C6: =IF('NEW POOL'!B167>0,1,0) -> 0 | D6: =B6*C6 -> 0
A7: Waterfeature: | B7: 10 | C7: ='NEW POOL'!B138+'NEW POOL'!B139+'NEW POOL'!B141+'NEW POOL'!B143 -> 0 | D7: =B7*C7 -> 0
A8: Soil Sample / Engineer: | B8: 750 | C8: ='NEW POOL'!B53 -> 1 | D8: =B8*C8 -> 750
A10: Plans Total: | D10: =SUM(D4:D9) -> 1160

Sheet EXC
A1: MARCH 2022
J2: Size over 1000
A3: Base | H3: Dig | J3: =IF(G5>1000,G5-1000,0) -> 0
A4: 0-400 | B4: 2700 | C4: =IF(G5<401,1,0) -> 0 | D4: =B4*C4 -> 0 | F4: Perimeter | G4: ='NEW POOL'!B7 -> 104 | H4: =G4*1.12 -> 116.48
A5: 401-450 | B5: =B4 -> 2700 | C5: =IF(C4>0,0,IF($G$5>400,IF($G$5<451,1,0))) -> 0 | D5: =B5*C5 -> 0 | F5: Surface | G5: ='NEW POOL'!B8 -> 576 | H5: =G5*1.15 -> 662.4
A6: 451-500 | B6: 2700 | C6: =IF(C4+C5>0,0,IF($G$5>450,IF($G$5<501,1,0))) -> 0 | D6: =B6*C6 -> 0 | F6: Min Depth | G6: ='NEW POOL'!B9 -> 3.5 | H6: =G6+1.25 -> 4.75
A7: 501-550 | B7: =B6 -> 2700 | C7: =IF(C4+C5+C6>0,0,IF($G$5>500,IF($G$5<551,1,0))) -> 0 | D7: =B7*C7 -> 0 | F7: Max Depth | G7: ='NEW POOL'!B10 -> 7 | H7: =G7+1.25 -> 8.25
A8: 551-600 | B8: =B7 -> 2700 | C8: =IF(C4+C5+C6+C7>0,0,IF($G$5>550,IF($G$5<601,1,0))) -> 1 | D8: =B8*C8 -> 2700 | F8: Avg Depth | G8: =(G6+G7)/2 -> 5.25 | H8: =(H6+H7)/2 -> 6.5
A9: 601-650 | B9: 2700 | C9: =IF(C4+C5+C6+C7+C8>0,0,IF($G$5>600,IF($G$5<651,1,0))) -> 0 | D9: =B9*C9 -> 0 | F9: Spa | G9: =IF(C27>0,50,0) -> 0 | H9: =IF(G9>0,75,0) -> 0
A10: 651-700 | B10: =B9 -> 2700 | C10: =IF(C4+C5+C6+C7+C8+C9>0,0,IF($G$5>650,IF($G$5<701,1,0))) -> 0 | D10: =B10*C10 -> 0
A11: 701-750 | B11: =B10 -> 2700 | C11: =IF(C4+C5+C6+C7+C8+C9+C10>0,0,IF($G$5>700,IF($G$5<751,1,0))) -> 0 | D11: =B11*C11 -> 0 | F11: Yardage Removed: | H11: =((H5*H8)/24)+((H9*2.5)/24) -> 179.4
A12: 751-800 | B12: 2750 | C12: =IF(C4+C5+C6+C7+C8+C9+C10+C11>0,0,IF($G$5>750,IF($G$5<801,1,0))) -> 0 | D12: =B12*C12 -> 0
A13: 801-850 | B13: 3000 | C13: =IF(C4+C5+C6+C7+C8+C9+C10+C11+C12>0,0,IF($G$5>800,IF($G$5<851,1,0))) -> 0 | D13: =B13*C13 -> 0
A14: 851-900 | B14: 3100 | C14: =IF(C4+C5+C6+C7+C8+C9+C10+C11+C12+C13>0,0,IF($G$5>850,IF($G$5<901,1,0))) -> 0 | D14: =B14*C14 -> 0
A15: 901-950 | B15: 3150 | C15: =IF(C4+C5+C6+C7+C8+C9+C10+C11+C12+C13+C14>0,0,IF($G$5>900,IF($G$5<951,1,0))) -> 0 | D15: =B15*C15 -> 0
A16: 951-1000 | B16: =B15 -> 3150 | C16: =IF(C4+C5+C6+C7+C8+C9+C10+C11+C12+C13+C14+C15>0,0,IF($G$5>950,IF($G$5<1001,1,0)))+IF('NEW POOL'!B8>1000,1,0) -> 0 | D16: =B16*C16 -> 0
A17: 1000+ | B17: 4 | C17: =J3 -> 0 | D17: =B17*C17 -> 0
D18: =SUM(D4:D17) -> 2700
A20: Add'l 6" Depth: | B20: 90 | C20: =IF('NEW POOL'!B10<8.05,0,('NEW POOL'!B10-8)*2) -> 0 | D20: =B20*C20 -> 0
A21: 6" RBB: | B21: 5 | C21: ='NEW POOL'!B32 -> 0 | D21: =B21*C21 -> 0
A22: 12" RBB: | B22: 6.5 | C22: ='NEW POOL'!B33 -> 0 | D22: =B22*C22 -> 0
A23: 18" RBB: | B23: 7.5 | C23: ='NEW POOL'!B34 -> 0 | D23: =B23*C23 -> 0
A24: 24" RBB: | B24: 8.5 | C24: ='NEW POOL'!B35 -> 0 | D24: =B24*C24 -> 0
A25: 30" RBB" | B25: 9 | C25: ='NEW POOL'!B36 -> 0 | D25: =B25*C25 -> 0
A26: 36" RBB: | B26: 10 | C26: ='NEW POOL'!B37 -> 0 | D26: =B26*C26 -> 0
A27: Base Spa: | B27: 200 | C27: =IF('NEW POOL'!B17>0,1,0) -> 0 | D27: =B27*C27 -> 0
A28: Raise Spa: | B28: 350 | C28: ='NEW POOL'!B18 -> 0 | D28: =B28*C28 -> 0
A29: Site Prep: | B29: 200 | C29: ='NEW POOL'!B45 -> 0 | D29: =B29*C29 -> 0
A30: Backfill: | B30: 600 | C30: 1 | D30: =B30*C30 -> 600
A31: Gravel: | B31: 1 | C31: ='NEW POOL'!B46*2.75 -> 2.75 | D31: =B31*C31*G5 -> 1584 | E31: Per 3" | G31: Dirt Haul Actual
A32: Dirt Haul: | B32: 18 | C32: ='NEW POOL'!B47*H11 -> 179.4 | D32: =B32*C32 -> 3229.2 | E32: Per Yard | G32: 600 | H32: Skid Steer | L32: =G32 -> 600
A33: Cover Box: | B33: 450 | C33: ='NEW POOL'!B49 -> 0 | D33: =B33*C33*'NEW POOL'!E7 -> 0 | E33: Per Ft | G33: 90 | H33: Hourly Driver | J33: 8 | L33: =G33*J33 -> 720
A34: Travel: | B34: 7 | C34: ='NEW POOL'!E10 -> 0 | D34: =B34*C34 -> 0 | G34: 85 | H34: Per Load | J34: 20 | L34: =G34*J34 -> 1700
A35: Misc: | B35: 75 | C35: 1 | D35: =B35*C35 -> 75
D36: =SUM(D20:D35) -> 5488.2 | L36: =SUM(L32:L35) -> 3020
D38: =D18+D36 -> 8188.2

Sheet PLUM
A1: MARCH 2022
A3: PLUMBING
A4: Short Stub | B4: 550 | C4: 1 | D4: =B4*C4 -> 550
A5: Spa Base: | B5: 750 | C5: =EXC!C27 -> 0 | D5: =B5*C5 -> 0
D6: =SUM(D4:D5) -> 550
A8: Pool Overun: | B8: 25 | C8: =IF('NEW POOL'!B58>33,'NEW POOL'!B58-33,0) -> 27 | D8: =B8*C8 -> 675 | E8: Over 33'
A9: Spa Overun: | B9: 22 | C9: =IF('NEW POOL'!B69>30,('NEW POOL'!B69-30),0) -> 0 | D9: =B9*C9 -> 0 | E9: Over33'
A10: 1/2" | B10: 3.25 | C10: =ROUNDUP(K10,0) -> 0 | D10: =B10*C10 -> 0 | K10: =SUM(E10:J10) -> 0
A11: 3/4" | B11: 3 | C11: =ROUNDUP(K11,0) -> 0 | D11: =B11*C11 -> 0 | K11: =SUM(E11:J11) -> 0
A12: 1" | B12: 3.5 | C12: =ROUNDUP(K12,0) -> 0 | D12: =B12*C12 -> 0 | E12: ='NEW POOL'!B61 -> 0 | K12: =SUM(E12:J12) -> 0
A13: 1.5" | B13: 4.5 | C13: =ROUNDUP(K13,0) -> 0 | D13: =B13*C13 -> 0 | E13: ='NEW POOL'!B62 -> 0 | K13: =SUM(E13:J13) -> 0
A14: 2.0" | B14: 5.5 | C14: =ROUNDUP(K14,0) -> 205 | D14: =B14*C14 -> 1127.5 | E14: ='NEW POOL'!B7 -> 104 | F14: ='NEW POOL'!B58 -> 60 | G14: ='NEW POOL'!B60 -> 0 | H14: ='NEW POOL'!B66+('NEW POOL'!B67*6*1.15) -> 0 | K14: =(SUM(E14:J14)*1.25) -> 205
A15: 2.5" | B15: 7 | C15: =ROUNDUP(K15,0) -> 70 | D15: =B15*C15 -> 490 | E15: ='NEW POOL'!B59 -> 70 | F15: 0 | G15: ='NEW POOL'!B17 -> 0 | K15: =SUM(E15:J15) -> 70
A16: 3.0" | B16: 8.75 | C16: =ROUNDUP(K16,0) -> 0 | D16: =B16*C16 -> 0 | K16: =SUM(E16:J16) -> 0
A17: W/F (1) | B17: =B14 -> 5.5 | C17: ='NEW POOL'!B62 -> 0 | D17: =K17 -> 0 | E17: 30 | F17: LNFT Inlcuded | H17: =IF('NEW POOL'!B62>0,1,0) -> 0 | I17: =IF('NEW POOL'!B62<($E$17+1),$E$17,'NEW POOL'!B62) -> 30 | J17: =H17*I17 -> 0 | K17: =((($E$18*H17)+((J17-$E$17)*B17)))*H17 -> 0
A18: W/F (2) | B18: =B17 -> 5.5 | C18: ='NEW POOL'!B63 -> 0 | D18: =K18 -> 0 | E18: 200 | F18: Base | H18: =IF('NEW POOL'!B63>0,1,0) -> 0 | I18: =IF('NEW POOL'!B63<($E$17+1),$E$17,'NEW POOL'!B63) -> 30 | J18: =H18*I18 -> 0 | K18: =((($E$18*H18)+((J18-$E$17)*B18)))*H18 -> 0
A19: W/F (3) | B19: =B18 -> 5.5 | C19: ='NEW POOL'!B64 -> 0 | D19: =K19 -> 0 | H19: =IF('NEW POOL'!B64>0,1,0) -> 0 | I19: =IF('NEW POOL'!B64<($E$17+1),$E$17,'NEW POOL'!B64) -> 30 | J19: =H19*I19 -> 0 | K19: =((($E$18*H19)+((J19-$E$17)*B19)))*H19 -> 0
A20: W/F (4) | B20: =B19 -> 5.5 | C20: ='NEW POOL'!B65 -> 0 | D20: =K20 -> 0 | H20: =IF('NEW POOL'!B65>0,1,0) -> 0 | I20: =IF('NEW POOL'!B65<($E$17+1),$E$17,'NEW POOL'!B65) -> 30 | J20: =H20*I20 -> 0 | K20: =((($E$18*H20)+((J20-$E$17)*B20)))*H20 -> 0
A21: Add'l W/F Run: | B21: =B13 -> 4.5 | C21: =E17+E18+E19+E20 -> 230 | D21: =B21*C21 -> 1035
A22: Add'l Main Drain: | B22: 275 | C22: ='NEW POOL'!B114+'NEW POOL'!B115 -> 0 | D22: =B22*C22 -> 0
A23: Manifold: | B23: 175 | C23: 1 | D23: =B23*C23 -> 175
A24: Heater Set: | B24: 300 | C24: =IF((E24+F24)=1,1,0) -> 0 | E24: =C5 -> 0 | F24: ='NEW POOL'!B121 -> 0
A25: Infloor: | B25: 10 | C25: =ROUNDUP(IF('NEW POOL'!B66+'NEW POOL'!B66>0,'NEW POOL'!B8*0.5,0),0) -> 0 | D25: =B25*C25 -> 0
A26: Conduit: | B26: 2.75 | C26: =ROUNDUP(('NEW POOL'!B71+'NEW POOL'!B72*1.25),0) -> 229 | D26: =B26*C26 -> 629.75
A27: Strip Forms | B27: 700 | C27: 1 | D27: =B27*C27 -> 700
A28: Travel: | B28: 5 | C28: 0 | D28: =B28*C28 -> 0
D30: =SUM(D10:D29)+D6 -> 4707.25
A32: GAS
A33: Base Set: | B33: 1500 | C33: =IF('NEW POOL'!B68>0,1,0) -> 0 | D33: =B33*C33 -> 0
A34: Add'l Run | B34: 11 | C34: =IF('NEW POOL'!B68>25,'NEW POOL'!B68-25,0) -> 0 | D34: =B34*C34 -> 0
D36: =SUM(D33:D35) -> 0
A38: EQ SET | E38: Remodel
A39: Base Set: | B39: 750 | C39: 1 | D39: =B39*C39 -> 750
A40: Add'l Pump(s): | B40: 150 | C40: =C22 -> 0 | D40: =B40*C40 -> 0 | E40: 100
A41: Ozone: | B41: 200 | C41: =IF(J41>0,1,0) -> 0 | D41: =B41*C41 -> 0 | E41: 75 | G41: =IF('NEW POOL'!$A$127=EQUIP!$M$54,1,0) -> 0 | H41: =IF('NEW POOL'!A128=EQUIP!M54,1,0) -> 0 | I41: =IF('NEW POOL'!A129=EQUIP!M54,1,0) -> 0 | J41: =SUM(G41:I41) -> 0
A42: =EQUIP!M55 -> Del Ozone with UV AOP unit with Degas | B42: 210 | C42: =IF(J42>0,1,0) -> 0 | D42: =B42*C42 -> 0 | E42: 100 | G42: =IF('NEW POOL'!A127=EQUIP!M55,1,0) -> 0 | H42: =IF('NEW POOL'!A128=EQUIP!M55,1,0) -> 0 | I42: =IF('NEW POOL'!A129=EQUIP!M55,1,0) -> 0 | J42: =SUM(G42:I42) -> 0
A43: Heater: | B43: 200 | C43: ='NEW POOL'!B121 -> 0 | D43: =B43*C43 -> 0 | E43: 200
A44: Pool Bonding: | B44: 125 | C44: 1 | D44: =B44*C44 -> 125
A45: Travel: | B45: 7 | C45: =C28 -> 0 | D45: =B45*C45 -> 0
D47: =SUM(D39:D46) -> 875
...

Sheet STEEL
A1: MARCH 2022
A3: STEEL
A4: Base: | B4: 25 | C4: ='NEW POOL'!B7 -> 104 | D4: =B4*C4 -> 2600
A5: 4-Bar Beam: | B5: 100 | C5: 1 | D5: =B5*C5 -> 100
A6: 10" OC: | B6: 0 | C6: =C4 -> 104 | D6: =B6*C6 -> 0
A7: Add'l 6" Depth: | B7: 100 | C7: =EXC!C20 -> 0 | D7: =B7*C7 -> 0 | E7: Per 6"
A8: Spa: | B8: 450 | C8: =EXC!C27 -> 0 | D8: =B8*C8 -> 0
A9: Raise Spa: | B9: 150 | C9: ='NEW POOL'!B18 -> 0 | D9: =B9*C9 -> 0
A10: Bench: | B10: 8 | C10: ='NEW POOL'!B11 -> 70 | D10: =B10*C10 -> 560
A11: 6" RBB: | B11: 3 | C11: ='NEW POOL'!B32 -> 0 | D11: =B11*C11 -> 0
A12: 12" RBB: | B12: 4 | C12: ='NEW POOL'!B33 -> 0 | D12: =B12*C12 -> 0
A13: 18" RBB: | B13: 5 | C13: ='NEW POOL'!B34 -> 0 | D13: =B13*C13 -> 0
A14: 24" RBB: | B14: 6 | C14: ='NEW POOL'!B35 -> 0 | D14: =B14*C14 -> 0
A15: 30" RBB: | B15: 7 | C15: ='NEW POOL'!B36 -> 0 | D15: =B15*C15 -> 0
A16: 36" RBB: | B16: 7 | C16: ='NEW POOL'!B37 -> 0 | D16: =B16*C16 -> 0
A17: Pool Bonding: | B17: 500 | C17: 1 | D17: =B17*C17 -> 500
A18: Bonding Lights: | B18: 0 | C18: ='NEW POOL'!B124+'NEW POOL'!B125 -> 2 | D18: =B18*C18 -> 0
A19: #4 in Floor: | B19: 0 | C19: =IF('NEW POOL'!B10>6,1,0) -> 1 | D19: =B19*C19 -> 0
A20: Depth over 8': | B20: 80 | C20: =IF('NEW POOL'!B10>8.1,1,0) -> 0 | D20: =B20*C20 -> 0
A21: Negative Edge: | B21: 750 | C21: 0 | D21: =B21*C21 -> 0
A22: Tanning Shelf: | B22: 275 | C22: ='NEW POOL'!B12 -> 0 | D22: =B22*C22 -> 0
A23: Muck Out: | B23: 100 | C23: 2 | D23: =B23*C23 -> 200
A24: Spa Double Curtain: | B24: 75 | C24: =IF('NEW POOL'!B14>0,1,0) -> 0 | D24: =B24*C24 -> 0
A25: Double Curtain: | B25: 35 | C25: ='NEW POOL'!B51 -> 0 | D25: =B25*C25 -> 0
A26: Travel: | B26: 7 | C26: ='NEW POOL'!E10 -> 0 | D26: =B26*C26 -> 0
D28: =SUM(D4:D27) -> 3960

Sheet ELEC
A1: MARCH 2022
A3: ELECTRICAL
A4: Base: | B4: 1650 | C4: 1 | D4: =B4*C4 -> 1650
A5: Homerun: | B5: 18 | C5: =IF('NEW POOL'!B71>E5,'NEW POOL'!B71-E5,0) -> 0 | D5: =B5*C5 -> 0 | E5: 65 | F5: Included
A6: Lights: | B6: 100 | C6: =IF(STEEL!C18>E6,STEEL!C18-E6) -> 1 | D6: =B6*C6 -> 100 | E6: 1 | F6: Included
A7: Heater: | B7: 255 | C7: ='NEW POOL'!B121 -> 0 | D7: =B7*C7 -> 0
A8: Heatpump: | B8: =450 -> 450 | C8: =IF('NEW POOL'!E121="",0,1) -> 0 | D8: =B8*C8 -> 0
A9: Add'l Heatpump: | B9: 6 | C9: =IF('NEW POOL'!B73>40,'NEW POOL'!B73-40,0) -> 0 | D9: =B9*C9 -> 0 | E9: 40 | F9: Included
A10: Salt System: | B10: 200 | C10: ='NEW POOL'!E127+'NEW POOL'!E128+'NEW POOL'!E129 -> 0 | D10: =B10*C10 -> 0
A11: Automation: | B11: 250 | C11: ='NEW POOL'!B131 -> 1 | D11: =B11*C11 -> 250
A12: Bonding: | B12: 300 | C12: 1 | D12: =B12*C12 -> 300
A13: Outlet: | B13: 85 | C13: 1 | D13: =B13*C13 -> 85
A14: Travel: | B14: 7 | C14: ='NEW POOL'!E10 -> 0 | D14: =B14*C14 -> 0
A15: Auto Fill Run: | B15: 3 | C15: ='NEW POOL'!B134 -> 0 | D15: =B15*C15 -> 0 | E15: =D15/0.7 -> 0
D17: =SUM(D4:D16) -> 2385

Sheet SHOT
A1: AUGUST 2022
C2: Interior Area: | D2: =((('NEW POOL'!B9+'NEW POOL'!B10)/2)*'NEW POOL'!B7)+'NEW POOL'!B8 -> 1122 | E2: Yardage: | F2: =ROUNDUP(((((('NEW POOL'!B7*1)+(D2*0.67))+('NEW POOL'!B38))/24)+((('NEW POOL'!B17*1)+('NEW POOL'!B17*3)+(40))/25)+('NEW POOL'!B167/10))*1.1,0)+('NEW POOL'!B51/20)+('NEW POOL'!B18*2) -> 41
A3: SHOTCRETE - LABOR | J3: ='NEW POOL'!A32 -> 6" RBB: | K3: ='NEW POOL'!B32 -> 0 | L3: =K3*0.5 -> 0
A4: Minimum Labor: | B4: 90 | C4: =E4 -> 32 | D4: =B4*C4 -> 2880 | E4: 32 | F4: Minimum Labor Yardage | J4: ='NEW POOL'!A33 -> 12" RBB: | K4: ='NEW POOL'!B33 -> 0 | L4: =K4*1 -> 0
A5: Add'l Labor: | B5: =B4 -> 90 | C5: =IF(F2>32,F2-32,0) -> 9 | D5: =B5*C5 -> 810 | E5: 75 | F5: Included | J5: ='NEW POOL'!A34 -> 18" RBB: | K5: ='NEW POOL'!B34 -> 0 | L5: =K5*1.5 -> 0
A6: Spa: | B6: 250 | C6: =EXC!C27 -> 0 | D6: =B6*C6 -> 0 | E6: 1 | F6: Included | J6: ='NEW POOL'!A35 -> 24" RBB: | K6: ='NEW POOL'!B35 -> 0 | L6: =K6*2 -> 0
A7: Auto Cover: | B7: 250 | C7: =K13*'NEW POOL'!B49 -> 0 | D7: =B7*C7 -> 0 | E7: Per 6" | J7: ='NEW POOL'!A36 -> 30" RBB: | K7: ='NEW POOL'!B36 -> 0 | L7: =K7*2.5 -> 0
A8: Distance 251 to 300 | B8: 500 | C8: =IF('NEW POOL'!E11=1,1,0) -> 0 | D8: =B8*C8 -> 0 | J8: ='NEW POOL'!A37 -> 36" RBB: | K8: ='NEW POOL'!B37 -> 0 | L8: =K8*3 -> 0
A9: Distance 301 to 350 | B9: 1000 | C9: =IF('NEW POOL'!E11=2,1,0) -> 0 | D9: =B9*C9 -> 0
A10: Travel: | B10: 7 | C10: ='NEW POOL'!E10 -> 0 | D10: =B10*C10 -> 0 | F10: =B5+B15 -> 318 | K10: SQFT: | L10: =SUM(L3:L9) -> 0
A12: Labor Total: | D12: =SUM(D4:D11) -> 3690 | J12: Auto Cover
J13: ='NEW POOL'!E7+2 -> 18 | K13: =ROUNDUP((J13*7/22),0) -> 6 | L13: =D7+D17 -> 0
A14: SHOTCRETE -MATERIAL
A15: Per Yard: | B15: 228 | C15: =F2 -> 41 | D15: =B15*C15 -> 9348
A16: Clean-Out: | B16: 125 | C16: 1 | D16: =B16*C16 -> 125
A17: Auto Cover: | B17: =B15 -> 228 | C17: =C7 -> 0 | D17: =B17*C17 -> 0
A18: Environ / Fuel: | B18: 25 | C18: =C15 -> 41 | D18: =B18*C18 -> 1025
A19: Miscelaneous: | B19: 150 | C19: 1 | D19: 125
A20: Travel: | B20: 7 | C20: ='NEW POOL'!E10 -> 0 | D20: =B20*C20 -> 0
C21: Sub Total: | D21: =SUM(D15:D20) -> 10623
A22: MECK: | B22: 0.025 | D22: =D21*B22 -> 265.575
A23: NC: | B23: 0.0475 | D23: =D21*B23 -> 504.5925
A25: Material Total: | D25: =D21+D22+D23 -> 11393.168
A27: Total Shotcrete: | D27: =D12+D25 -> 15083.168

Sheet TILE COPING
A1: MAY 2022
A3: TILE | G3: TILE - RBB & COLUMNS
A4: Labor - Pool: | B4: 10 | C4: ='NEW POOL'!B7 -> 104 | D4: =B4*C4 -> 1040 | G4: ='NEW POOL'!A32 -> 6" RBB: | H4: ='NEW POOL'!B32 -> 0 | I4: =IF('NEW POOL'!C32=1,1,0) -> 0 | J4: =H4*0.5*I4 -> 0
A5: Material - Level 1 - Pool: | B5: 7 | C5: =$C$4*E5 -> 104 | D5: =B5*C5 -> 728 | E5: =IF('NEW POOL'!B81="INCLUDED",1,0) -> 1 | F5: Included | G5: ='NEW POOL'!A33 -> 12" RBB: | H5: ='NEW POOL'!B33 -> 0 | I5: =IF('NEW POOL'!C33=1,1,0) -> 0 | J5: =H5*2*I5 -> 0
A6: Material - Level 2 - Pool: | B6: 20 | C6: =$C$4*'NEW POOL'!B82 -> 0 | D6: =B6*C6 -> 0 | F6: Included | G6: ='NEW POOL'!A34 -> 18" RBB: | H6: ='NEW POOL'!B34 -> 0 | I6: =IF('NEW POOL'!C34=1,1,0) -> 0 | J6: =H6*3*I6 -> 0
A7: Material - Level 3 - Pool: | B7: 50 | C7: =$C$4*'NEW POOL'!B83 -> 0 | D7: =B7*C7 -> 0 | G7: ='NEW POOL'!A35 -> 24" RBB: | H7: ='NEW POOL'!B35 -> 0 | I7: =IF('NEW POOL'!C35=1,1,0) -> 0 | J7: =H7*4*I7 -> 0
A8: Labor - Spa: | B8: =B4 -> 10 | C8: ='NEW POOL'!B17 -> 0 | D8: =B8*C8 -> 0 | G8: ='NEW POOL'!A36 -> 30" RBB: | H8: ='NEW POOL'!B36 -> 0 | I8: =IF('NEW POOL'!C36=1,1,0) -> 0 | J8: =H92*I8 -> 0
A9: Material - Level 1 - Spa: | B9: =B5 -> 7 | C9: =$C$8*E9 -> 0 | D9: =B9*C9 -> 0 | E9: =E5 -> 1 | G9: ='NEW POOL'!A37 -> 36" RBB: | H9: ='NEW POOL'!B37 -> 0 | I9: =IF('NEW POOL'!C37=1,1,0) -> 0 | J9: =H9*6*I9 -> 0
A10: Material - Level 2 - Spa: | B10: =B6 -> 20 | C10: =$C$8*'NEW POOL'!B82 -> 0 | D10: =B10*C10 -> 0 | G10: Columns: | H10: =H48 -> 0 | I10: =IF('NEW POOL'!C40=1,1,0) -> 0 | J10: =H10*I10*((('NEW POOL'!$B$41*'NEW POOL'!$B$43*2)+('NEW POOL'!$B$42*'NEW POOL'!$B$43*2))*2) -> 0
A11: Material - Level 3 - Spa: | B11: =B7 -> 50 | C11: =$C$8*'NEW POOL'!B83 -> 0 | D11: =B11*C11 -> 0 | I11: LNFT | J11: =SUM(J4:J10) -> 0
A12: Labor - Other: | B12: =B8 -> 10 | C12: =J14+J11+'NEW POOL'!B77 -> 0 | D12: =B12*C12 -> 0 | M12: ='NEW POOL'!B82+'NEW POOL'!B83 -> 0
A13: Material - Level 1 - Other: | B13: =B9 -> 7 | C13: =IF(M12=1,0,'TILE COPING'!C12) -> 0 | D13: =B13*C13 -> 0 | E13: =E5 -> 1 | G13: SPA FACING
A14: Material - Level 2 - Other: | B14: =B10 -> 20 | C14: =C12*'NEW POOL'!B82 -> 0 | D14: =B14*C14 -> 0 | G14: Tile: | H14: ='NEW POOL'!$B$18 -> 0 | I14: =IF('NEW POOL'!B19=1,1,0) -> 0 | J14: =ROUNDUP(((H14*I14*'NEW POOL'!$B$17*3)*1.1),0) -> 0 | K14: LNFT
A15: Material - Level 3 - Other: | B15: =B11 -> 50 | C15: =C12*'NEW POOL'!B83 -> 0 | D15: =B15*C15 -> 0 | G15: Panel: | H15: ='NEW POOL'!$B$18 -> 0 | I15: =IF('NEW POOL'!B19=2,1,0) -> 0 | J15: =ROUNDUP(((H15*I15*'NEW POOL'!$B$17*1.5)*1.1),0) -> 0 | K15: SQFT
A16: Trim Tile - Labor: | B16: 10 | C16: =('NEW POOL'!B11+('NEW POOL'!B17*0.8))*'NEW POOL'!B79 -> 0 | D16: =B16*C16 -> 0 | G16: Stacked: | H16: ='NEW POOL'!$B$18 -> 0 | I16: =IF('NEW POOL'!B19=3,1,0) -> 0 | J16: =ROUNDUP(((H16*I16*'NEW POOL'!$B$17*1.5)*1.1),0) -> 0 | K16: SQFT
A17: Trim Tile - Material: | B17: 4 | C17: =C16 -> 0 | D17: =B17*C17 -> 0
A18: Travel: | B18: 7 | C18: ='NEW POOL'!E10 -> 0 | D18: =B18*C18 -> 0 | F18: REMODEL | J18: Pool | K18: =REMODEL!B7 -> 80
F19: Labor - Remove & Replace Tile | I19: 19.5 | J19: Spa | K19: =REMODEL!B17 -> 0
A20: Tile Total: | D20: =SUM(D4:D19) -> 1768 | F20: Skimmers | I20: 50 | J20: Skimmers | K20: =REMODEL!B37 -> 1
F21: =A5 -> Material - Level 1 - Pool: | I21: =B5 -> 7 | J21: =IF(REMODEL!B39="INCLUDED",1,0) -> 1
A22: COPING / DECKING - LABOR | F22: =A6 -> Material - Level 2 - Pool: | I22: =B6 -> 20 | J22: =REMODEL!B40 -> 0
A23: Paver Coping - Labor: | B23: 12 | C23: =ROUNDUP((('NEW POOL'!$B$7*1.1)+('NEW POOL'!$B$17*2.15)),0)*'NEW POOL'!B87 -> 0 | D23: =B23*C23 -> 0 | E23: LNFT | F23: =A7 -> Material - Level 3 - Pool: | I23: =B7 -> 50 | J23: =REMODEL!B41 -> 0
A24: Paver Decking - Labor: | B24: 8 | C24: ='NEW POOL'!E9*1.05*'NEW POOL'!B88 -> 875.7 | D24: =B24*C24 -> 7005.6 | E24: SQFT | F24: Remove Joint / Install Caulk | I24: 7.5
A25: Travertine Coping - Labor: | B25: =B23 -> 12 | C25: =ROUNDUP((('NEW POOL'!$B$7*1.1)+('NEW POOL'!$B$17*2.15)),0)*('NEW POOL'!B90+'NEW POOL'!B93) -> 115 | D25: =B25*C25 -> 1380 | E25: LNFT | F25: Crack Repair | I25: 22
A26: Travertine Decking - Labor: | B26: =B24 -> 8 | C26: ='NEW POOL'!E9*1.05*('NEW POOL'!B91+'NEW POOL'!B94) -> 0 | D26: =B26*C26 -> 0 | E26: SQFT | F26: Coping: | G26: =DEMO!D6 -> 0
A27: Flagstone Coping - Labor: | B27: 15 | C27: =ROUNDUP((('NEW POOL'!$B$7*1.1)+('NEW POOL'!$B$17*2.15)),0)*'NEW POOL'!B85 -> 0 | D27: =B27*C27 -> 0 | F27: Decking: | G27: =REMODEL!E9 -> 0
A28: Concrete Decking - Cantilever: | B28: 16.5 | C28: =('NEW POOL'!B7*'NEW POOL'!B96)*'NEW POOL'!B96 -> 0 | D28: =B28*C28 -> 0 | E28: SQFT
A29: Concrete Pump | B29: 600 | C29: =IF(('NEW POOL'!B96+'NEW POOL'!B97)>0,1,0) -> 0 | D29: =B29*C29 -> 0
A30: Concrete Steps: | B30: 27 | C30: ='NEW POOL'!B98 -> 0 | D30: =B30*C30 -> 0 | F30: Ivory, Hazelnut, Noce, Country Classic, Light Noce, Harvest Blend
A31: Total Labor: | D31: =SUM(D23:D30) -> 8385.6 | F31: Ivory, Hazelnut, Noce, Country Classic, Light Noce, Harvest Blend
F32: Silver, Silver Vogue, River Silver, Bianco Dolomite, Dianna Royal, Skyline, Alaska Silver, Turkish Carrea
A33: COPING / DECKING - MATERIAL | F33: Silver, Silver Vogue, River Silver, Bianco Dolomite, Dianna Royal, Skyline, Alaska Silver, Turkish Carrea
A34: Paver Coping - Material: | B34: 9 | C34: =C23 -> 0 | D34: =B34*C34 -> 0 | E34: LNFT | F34: =1000+120 -> 1120 | G34: 90 | I34: Base | J34: Add'l
A35: Paver Decking - Material: | B35: 3.25 | C35: =C24 -> 875.7 | D35: =B35*C35 -> 2846.025 | E35: SQFT | G35: 4' Band on Pool: | H35: ='NEW POOL'!B97 -> 0 | I35: =(H35*'NEW POOL'!B7*4)*1.1 -> 0 | J35: ='NEW POOL'!E9-'TILE COPING'!I35 -> 834
A36: Travertine Coping - Level 1: | B36: 11 | C36: =IF('NEW POOL'!B90=1,C25,0) -> 0 | D36: =B36*C36 -> 0 | E36: LNFT
A37: Travertine Decking - Level 1: | B37: 7.5 | C37: =IF('NEW POOL'!B91=1,C26,0) -> 0 | D37: =B37*C37 -> 0 | E37: SQFT
A38: Travertine Coping - Level 2: | B38: 12 | C38: =IF('NEW POOL'!B93=1,C25,0) -> 115 | D38: =B38*C38 -> 1380 | E38: LNFT
A39: Travertine Decking - Level 2: | B39: 9.75 | C39: =IF('NEW POOL'!B94=1,C26,0) -> 0 | D39: =B39*C39 -> 0 | E39: SQFT
A40: Flagstone - Material | B40: 25 | C40: ='NEW POOL'!B85*'NEW POOL'!B7 -> 0 | D40: =B40*C40 -> 0 | E40: LNFT
A41: Concrete Decking - Base: | B41: 7 | C41: =CEILING(I35,10) -> 0 | D41: =B41*C41 -> 0 | E41: SQFT | G41: PANEL LEDGE - RBB & COLUMNS | L41: STACKED STONE - RBB & COLUMNS
...

Sheet MASONRY
A1: AUGUST 2023
A3: Retaining Walls
B4: Total Height | C4: $/SQFT | D4: $/LNFT | E4: LNFT | F4: COST
A5: No Retaining Wall | B5: 0 | C5: 0 | D5: 0 | E5: 0 | F5: 0
A6: 12" High - Standard | B6: 2 | C6: 50 | D6: =B6*C6 -> 100 | E6: ='NEW POOL'!B171 -> 0 | F6: =D6*E6 -> 0
A7: 24" High - Standard | B7: 3 | C7: =C6 -> 50 | D7: =B7*C7 -> 150 | E7: =E6 -> 0 | F7: =D7*E7 -> 0
A8: 36" High - Standard | B8: 4 | C8: =C7 -> 50 | D8: =B8*C8 -> 200 | E8: =E7 -> 0 | F8: =D8*E8 -> 0
A9: 48" High - Standard | B9: 5 | C9: =C8 -> 50 | D9: =B9*C9 -> 250 | E9: =E8 -> 0 | F9: =D9*E9 -> 0
A10: 12" High - CMU - Veneer Facing - 1-Side | B10: =B6 -> 2 | C10: 65 | D10: =B10*C10 -> 130 | E10: =E9 -> 0 | F10: =D10*E10 -> 0
A11: 24" High - CMU - Veneer Facing - 1-Side | B11: =B7 -> 3 | C11: =C10 -> 65 | D11: =B11*C11 -> 195 | E11: =E10 -> 0 | F11: =D11*E11 -> 0
A12: 36" High - CMU - Veneer Facing - 1-Side | B12: =B8 -> 4 | C12: =C11 -> 65 | D12: =B12*C12 -> 260 | E12: =E11 -> 0 | F12: =D12*E12 -> 0
A13: 48" High - CMU - Veneer Facing - 1-Side | B13: =B9 -> 5 | C13: =C12 -> 65 | D13: =B13*C13 -> 325 | E13: =E12 -> 0 | F13: =D13*E13 -> 0
A14: 12" High - CMU - Veneer Facing - 2-Sides | B14: =B10 -> 2 | C14: 75 | D14: =B14*C14 -> 150 | E14: =E13 -> 0 | F14: =D14*E14 -> 0
A15: 24" High - CMU - Veneer Facing - 2-Sides | B15: =B11 -> 3 | C15: =C14 -> 75 | D15: =B15*C15 -> 225 | E15: =E14 -> 0 | F15: =D15*E15 -> 0
A16: 36" High - CMU - Veneer Facing - 2-Sides | B16: =B12 -> 4 | C16: =C15 -> 75 | D16: =B16*C16 -> 300 | E16: =E15 -> 0 | F16: =D16*E16 -> 0
A17: 48" High - CMU - Veneer Facing - 2-Sides | B17: =B13 -> 5 | C17: =C16 -> 75 | D17: =B17*C17 -> 375 | E17: =E16 -> 0 | F17: =D17*E17 -> 0
A18: Includes 12" Footer

Sheet DEMO
A1: March 2023
A3: DEMO
A4: Cut | B4: 2.8 | C4: =IF(C5=1,0,1) -> 0 | D4: =INT!E23 -> 1122 | E4: =B4*D4*C4 -> 0
A5: Full Chip Out | B5: 3.5 | C5: =REMODEL!B24 -> 1 | D5: =D4 -> 1122 | E5: =B5*D5*C5 -> 3927
A6: Remove Coping | B6: 20 | C6: =REMODEL!B25 -> 0 | D6: =(REMODEL!B7+REMODEL!B17)*REMODEL!B25 -> 0 | E6: =B6*C6*D6 -> 0
A7: Remove Decking | B7: 4 | C7: =REMODEL!B26 -> 0 | E7: =B7*C7 -> 0
E11: =SUM(E4:E10) -> 3927

Sheet INT
A1: FEBRUARY 2023
A3: INTERIOR | E3: =SHOT!D2 -> 1122 | O3: Retail | P3: Upgrade | Q3: Rounded
A4: 1 | B4: 2 | C4: 3 | D4: 4 | E4: 5 | F4: 6 | G4: 7 | H4: 8 | I4: 9 | J4: 10 | K4: 11 | L4: 12 | M4: 13 | N4: 14 | O4: 15 | P4: 16 | Q4: 17 | R4: 18
E5: Spa | H5: Pool Prep | I5: Spa Prep | J5: Drains | K5: Vac | L5: Returns | M5: Hydro | N5: Total | O5: 0.7
A6: Ivory Quartz | B6: 5.5 | C6: =IF(E3<851,850,E3) -> 1122 | D6: =B6*C6 -> 6171 | E6: 850 | F6: =EXC!C27 -> 0 | G6: =E6*F6 -> 0 | H6: 850 | I6: =D25 -> 0 | J6: =('NEW POOL'!B113+'NEW POOL'!B114+'NEW POOL'!B115)*2*15 -> 30 | K6: ='NEW POOL'!B119*20 -> 0 | L6: 20 | M6: 60 | N6: =SUM(G6:M6)+D6 -> 7131 | O6: =N6/$O$5 -> 10187.143 | R6: Ivory / Blue / French Grey / Super Blue / Mariner Blue / Tropical Blue / Sky Blue
A7: Pebble Tec - Level 1 | B7: 6.3 | C7: =IF(E3<851,850,E3) -> 1122 | D7: =B7*C7 -> 7068.6 | E7: 1150 | F7: =F6 -> 0 | G7: =E7*F7 -> 0 | H7: =H6 -> 850 | I7: =I6 -> 0 | J7: =J6 -> 30 | K7: =K6 -> 0 | L7: 20 | M7: 60 | N7: =SUM(G7:M7)+D7 -> 8028.6 | O7: =N7/$O$5 -> 11469.429 | P7: =O7-O6 -> 1282.2857 | Q7: =CEILING(P7,10) -> 1290 | R7: Caribbean Blue / Sandy Beach / Tahoe Blue / White Pearl
A8: Pebble Tec - Level 2 | B8: 7.9 | C8: =IF(E3<851,850,E3) -> 1122 | D8: =B8*C8 -> 8863.8 | E8: =E7 -> 1150 | F8: =F6 -> 0 | G8: =E8*F8 -> 0 | H8: =H7 -> 850 | I8: =I7 -> 0 | J8: =J6 -> 30 | K8: =K7 -> 0 | L8: 20 | M8: 60 | N8: =SUM(G8:M8)+D8 -> 9823.8 | O8: =N8/$O$5 -> 14034 | P8: =O8-$O$6 -> 3846.8571 | Q8: =CEILING(P8,10) -> 3850 | R8: Black Marble / Black Pearl / Blue Lagood / Blue Wave
A9: Pebble Tec - Level 3 | B9: 8.85 | C9: =IF(E3<851,850,E3) -> 1122 | D9: =B9*C9 -> 9929.7 | E9: =E8 -> 1150 | F9: =F8 -> 0 | G9: =E9*F9 -> 0 | H9: =H8 -> 850 | I9: =I8 -> 0 | J9: =J8 -> 30 | K9: =K8 -> 0 | L9: 20 | M9: 60 | N9: =SUM(G9:M9)+D9 -> 10889.7 | O9: =N9/$O$5 -> 15556.714 | P9: =O9-$O$6 -> 5369.5714 | Q9: =CEILING(P9,10) -> 5370 | R9: Crème de Menthe / Emerald Bay / Midnight Blue / Moonlight Grey / Sky Blue / Soft White / Tropical Breeze
A10: Pebble Sheen - Level 1 | B10: 6.75 | C10: =IF(E3<851,850,E3) -> 1122 | D10: =B10*C10 -> 7573.5 | E10: 1250 | F10: =F9 -> 0 | G10: =E10*F10 -> 0 | H10: =H9 -> 850 | I10: =I9 -> 0 | J10: =J9 -> 30 | K10: =K9 -> 0 | L10: 20 | M10: 60 | N10: =SUM(G10:M10)+D10 -> 8533.5 | O10: =N10/$O$5 -> 12190.714 | P10: =O10-$O$6 -> 2003.5714 | Q10: =CEILING(P10,10) -> 2010 | R10: Bordeaux / Desert Gold / French Grey / Irish Mist / White Diamonds / HighTech Caribbean Blue / High Tech Tahoe Blue
A11: Pebble Sheen - Level 2 | B11: 7.85 | C11: =IF(E3<851,850,E3) -> 1122 | D11: =B11*C11 -> 8807.7 | E11: =E10 -> 1250 | F11: =F10 -> 0 | G11: =E11*F11 -> 0 | H11: =H10 -> 850 | I11: =I10 -> 0 | J11: =J10 -> 30 | K11: =K10 -> 0 | L11: 20 | M11: 60 | N11: =SUM(G11:M11)+D11 -> 9767.7 | O11: =N11/$O$5 -> 13953.857 | P11: =O11-$O$6 -> 3766.7143 | Q11: =CEILING(P11,10) -> 3770 | R11: Aqua Blue / Blue Granite / Black Onyx / Blue Surf / Black Eclipse
A12: Pebble Sheen - Level 3 | B12: 9.25 | C12: =IF(E3<851,850,E3) -> 1122 | D12: =B12*C12 -> 10378.5 | E12: =E11 -> 1250 | F12: =F11 -> 0 | G12: =E12*F12 -> 0 | H12: =H11 -> 850 | I12: =I11 -> 0 | J12: =J11 -> 30 | K12: =K11 -> 0 | L12: 20 | M12: 60 | N12: =SUM(G12:M12)+D12 -> 11338.5 | O12: =N12/$O$5 -> 16197.857 | P12: =O12-$O$6 -> 6010.7143 | Q12: =CEILING(P12,10) -> 6020 | R12: Artic White / Cool Blue / Ocean Blue / Prism Blue / Slate Blue / Turtle Bay
A13: Pebble Fina - Level 1 | B13: 7.75 | C13: =IF(E3<851,850,E3) -> 1122 | D13: =B13*C13 -> 8695.5 | E13: 1050 | F13: =F12 -> 0 | G13: =E13*F13 -> 0 | H13: =H9 -> 850 | I13: =I9 -> 0 | J13: =J9 -> 30 | K13: =K12 -> 0 | L13: 20 | M13: 60 | N13: =SUM(G13:M13)+D13 -> 9655.5 | O13: =N13/$O$5 -> 13793.571 | P13: =O13-$O$6 -> 3606.4286 | Q13: =CEILING(P13,10) -> 3610 | R13: Acquos / Bella Blue / Classico / Grigio / Steel Grey
A14: Pebble Fina - Level 2 | B14: 10 | C14: =IF(E3<851,850,E3) -> 1122 | D14: =B14*C14 -> 11220 | E14: 1675 | F14: =F13 -> 0 | G14: =E14*F14 -> 0 | H14: =H13 -> 850 | I14: =I13 -> 0 | J14: =J13 -> 30 | K14: =K13 -> 0 | L14: 20 | M14: 60 | N14: =SUM(G14:M14)+D14 -> 12180 | O14: =N14/$O$5 -> 17400 | P14: =O14-$O$6 -> 7212.8571 | Q14: =CEILING(P14,10) -> 7220 | R14: Cielo Blue / Egyptian Sand / Fresca Verde
A15: Pebble Brilliance | B15: 17 | C15: =IF(E3<851,850,E3) -> 1122 | D15: =B15*C15 -> 19074 | E15: 1050 | F15: =F14 -> 0 | G15: =E15*F15 -> 0 | H15: =H14 -> 850 | I15: =I14 -> 0 | J15: =J14 -> 30 | K15: =K14 -> 0 | L15: 20 | M15: 60 | N15: =SUM(G15:M15)+D15 -> 20034 | O15: =N15/$O$5 -> 28620 | P15: =O15-$O$6 -> 18432.857 | Q15: =CEILING(P15,10) -> 18440 | R15: All Colors
A16: Pebble Breeze | B16: 23 | C16: =IF(E3<851,850,E3) -> 1122 | D16: =B16*C16 -> 25806 | E16: 1150 | F16: =F12 -> 0 | G16: =E16*F16 -> 0 | H16: =H12 -> 850 | I16: =I12 -> 0 | J16: =J12 -> 30 | K16: =K15 -> 0 | L16: 20 | M16: 60 | N16: =SUM(G16:M16)+D16 -> 26766 | O16: =N16/$O$5 -> 38237.143 | P16: =O16-$O$6 -> 28050 | Q16: =CEILING(P16,10) -> 28050 | R16: All Colors
A17: Pebble Essence | B17: 17.5 | C17: =IF(E3<851,850,E3) -> 1122 | D17: =B17*C17 -> 19635 | E17: 1150 | F17: =F16 -> 0 | G17: =E17*F17 -> 0 | H17: =H16 -> 850 | I17: =I16 -> 0 | J17: =J16 -> 30 | K17: =K16 -> 0 | L17: 20 | M17: 60 | N17: =SUM(G17:M17)+D17 -> 20595 | O17: =N17/$O$5 -> 29421.429 | P17: =O17-$O$6 -> 19234.286 | Q17: =CEILING(P17,10) -> 19240 | R17: All Colors
B18: 0 | C18: =C17 -> 1122 | D18: =B18*C18 -> 0 | E18: 1150 | F18: =F17 -> 0 | G18: =E18*F18 -> 0 | H18: =H17 -> 850 | I18: =I17 -> 0 | J18: =J17 -> 30 | K18: =K17 -> 0 | L18: 20 | M18: 60 | N18: =SUM(G18:M18)+D18 -> 960 | O18: =N18/$O$5 -> 1371.4286 | P18: =O18-$O$6 -> -8815.7143 | Q18: =CEILING(P18,10) -> -8810
A20: Misc: | B20: 100 | C20: 1 | D20: =B20*C20 -> 100
A21: Travel: | B21: 10 | C21: ='NEW POOL'!E10 -> 0 | D21: =B21*C21 -> 0
A22: Step & Bench Detail: | B22: 20 | C22: =IF('NEW POOL'!B11>20,'NEW POOL'!B11-20,0) -> 50 | D22: =B22*C22 -> 1000
A23: Pool Prep up to 1,200: | B23: 750 | C23: 1 | D23: =B23*C23 -> 750 | E23: =(('NEW POOL'!B7*(('NEW POOL'!B9+'NEW POOL'!B10)/2))+'NEW POOL'!B8) -> 1122
A24: Prep over 1,200: | B24: 1 | C24: =IF(E23>1200,E23-1200,0) -> 0 | D24: =B24*C24 -> 0
A25: Spa Prep: | B25: 250 | C25: =IF('NEW POOL'!B17>0,1,0) -> 0 | D25: =B25*C25 -> 0
A27: Water Truck - Shotcrete | C27: =_xlfn.CEILING.MATH(E27/7000,0.5) -> 3.5 | E27: ='NEW POOL'!E13 -> 22990 | F27: Gallons
A28: Full Truck: | B28: 490 | C28: =C27 -> 3.5 | D28: =B28*C28 -> 1715 | E28: 7,000 Gallons
A30: Microglass - Shotcrete
A31: Pool - SQFT: | B31: 0 | C31: =E31 -> 1122 | D31: =B31*C31 -> 0 | E31: =(('NEW POOL'!B7*(('NEW POOL'!B9+'NEW POOL'!B10)/2)))+'NEW POOL'!B8 -> 1122 | F31: IA
A32: Spa - SQFT: | B32: =B31 -> 0 | C32: =E32 -> 0 | D32: =B32*C32 -> 0 | E32: =(('NEW POOL'!B14*'NEW POOL'!B15)+((('NEW POOL'!B14*2)+('NEW POOL'!B15*2))*1.7)) -> 0 | F32: IA
A33: Raised Spa: | B33: 300 | C33: ='NEW POOL'!B18 -> 0 | D33: =B33*C33 -> 0
D34: =SUM(D31:D33) -> 0
A36: Premium Start-Up

Sheet REMODEL
A1: 2023 REMODEL PRICING MASTER - MARCH
A3: CUSTOMER NAME:
A4: CITY:
A5: Additional Layout: | B5: 0
A7: Perimeter: | B7: 80 | C7: LNFT | D7: Max Width: | E7: 17 | F7: FT | K7: =IF(#REF!+#REF!+#REF!>0,1,0) -> #REF!
A8: Surface Area: | B8: 400 | C8: SQFT | D8: Max Length: | E8: 30 | F8: FT
A9: Shallow Depth: | B9: 3.5 | C9: FT | D9: New Decking: | E9: 0 | F9: SQFT
A10: End Depth: | B10: 6 | C10: FT | D10: Travel: | E10: 0 | F10: MILES
A11: Total Step & Bench: | B11: 20 | C11: LNFT | D11: Pool to Street: | E11: 0 | F11: ( 1 if 251 to 300, 2 if 300 to 350)
A12: Tanning Shelf: | B12: 1 | C12: 1 for Yes, 0 for No
D13: Approx. Gallons: | E13: =_xlfn.CEILING.MATH(((B8*((B9+B10)/2))*7.6),10)-(B12*850) -> 13590
A14: Spa Length: | B14: 0
A15: Spa Width: | B15: 0
A16: Spa Shape: | B16: 0 | C16: ( 1 for Round, 2 for Square )
A17: Spa Perimeter: | B17: =ROUNDUP(IF(B16=1,(B14*3.14),(B14*2+B15*2)),0) -> 0
A18: Raised Spa?: | B18: 0 | C18: ( 1 for Yes, 0 for No) | E18: (Raised Spa = +18")
A19: Raised Spa Facing: | B19: 0 | C19: ( 1=Tile / 2=Ledgstone / 3=Stacked Stone)
A22: DEMOLITION
A24: Chip Out - Existing Interior: | B24: 1
A25: Remove Coping: | B25: 0
A26: Remove Exsiting Decking: | B26: 0 | C26: SQFT
A28: TILE / COPING / DECKING
A30: Remove & Replace Tile: | B30: 1
A31: Additional Tile Remove & Replace: | B31: 0 | C31: SQFT
A32: Remove Expansion Between Tile & Coping: | B32: 0
A33: Crack Repair | B33: 0 | C33: LNFT
A35: Add Trim Tile to Steps & Bench | B35: 0
A37: Number of Skimmers: | B37: 1
A39: Level 1 Tile | B39: =IF(B30>0,"INCLUDED",0) -> INCLUDED
A40: Upgrade Tile - Level 2 | B40: 0
A41: Upgrade Tile - Level 3 | B41: 0
A43: Flagstone Coping: | B43: 0 | C43: Enter "1" to Select
A45: Paver Coping: | B45: 0 | C45: Enter "1" to Select
A46: Paver Decking: | B46: 0 | C46: Enter "1" to Select
A48: Travertine Coping - Level 1: | B48: 0 | C48: Enter "1" to Select | E48: ='TILE COPING'!F30 -> Ivory, Hazelnut, Noce, Country Classic, Light Noce, Harvest Blend
A49: Travertine Decking - Level 1: | B49: 0 | C49: Enter "1" to Select | E49: ='TILE COPING'!F31 -> Ivory, Hazelnut, Noce, Country Classic, Light Noce, Harvest Blend
A51: Travertine Coping - Level 2: | B51: 0 | C51: Enter "1" to Select | E51: ='TILE COPING'!F32 -> Silver, Silver Vogue, River Silver, Bianco Dolomite, Dianna Royal, Skyline, Alaska Silver, Turkish Carrea
A52: Travertine Decking - Level 2: | B52: 0 | C52: Enter "1" to Select | E52: ='TILE COPING'!F33 -> Silver, Silver Vogue, River Silver, Bianco Dolomite, Dianna Royal, Skyline, Alaska Silver, Turkish Carrea
A54: Concrete Coping: | B54: 0 | C54: Enter "1" to Select
A55: Concrete Decking: | B55: 0 | C55: Enter "1" to Select
...

Sheet COST - REMODEL
A2: PLANS & ENGINEERING
A3: =PLANS!A4 -> Pool Only: | B3: =PLANS!B4 -> 410 | C3: =PLANS!C4 -> 1 | D3: =PLANS!D4 -> 410
A4: =PLANS!A5 -> Spa: | B4: =PLANS!B5 -> 80 | C4: =PLANS!C5 -> 0 | D4: =PLANS!D5 -> 0
A5: =PLANS!A6 -> Waterfall: | B5: =PLANS!B6 -> 15 | C5: =PLANS!C6 -> 0 | D5: =PLANS!D6 -> 0
A6: =PLANS!A7 -> Waterfeature: | B6: =PLANS!B7 -> 10 | C6: =PLANS!C7 -> 0 | D6: =PLANS!D7 -> 0
A7: =PLANS!A8 -> Soil Sample / Engineer: | B7: =PLANS!B8 -> 750 | C7: =PLANS!C8 -> 1 | D7: =PLANS!D8 -> 750
A9: PLANS & ENGINEERING TOTAL | D9: 0
A11: LAYOUT
A12: Pool Only | B12: 50 | C12: 1 | D12: =B12*C12 -> 50
A13: Spa | B13: 15 | C13: =EXC!C27 -> 0 | D13: =B13*C13 -> 0
A14: Silt Fencing, Etc. | B14: 500 | C14: ='NEW POOL'!B5 -> 1 | D14: =B14*C14 -> 500
A16: LAYOUT TOTAL | D16: =SUM(D12:D15) -> 550
A18: PERMIT
A19: Pool Only: | B19: 850 | C19: 0 | D19: =B19*C19 -> 0
A20: Spa: | B20: 150 | C20: =EXC!C27 -> 0 | D20: =B20*C20 -> 0
A21: Permit Runner: | B21: 75 | C21: 0 | D21: =B21*C21 -> 0
A23: PERMIT TOTAL | D23: =SUM(D19:D22) -> 0
A25: DEMO
A26: =DEMO!A4 -> Cut | B26: =DEMO!B4 -> 2.8 | C26: =DEMO!C4*DEMO!D4 -> 0 | D26: =DEMO!E4 -> 0
A27: =DEMO!A5 -> Full Chip Out | B27: =DEMO!B5 -> 3.5 | C27: =DEMO!C5*DEMO!D5 -> 1122 | D27: =DEMO!E5 -> 3927
A28: =DEMO!A6 -> Remove Coping | B28: =DEMO!B6 -> 20 | C28: =DEMO!D6 -> 0 | D28: =DEMO!E6 -> 0
A29: =DEMO!A7 -> Remove Decking | B29: =DEMO!B7 -> 4 | C29: =DEMO!C7 -> 0 | D29: =DEMO!E7 -> 0
A30: Remove Joint / Install Caulking | B30: ='TILE COPING'!I24 -> 7.5 | C30: =(REMODEL!B7+REMODEL!B17)*REMODEL!B32 -> 0 | D30: =B30*C30 -> 0
A32: DEMO TOTAL | D32: =SUM(D26:D31) -> 3927
A34: EXCAVATION
A35: Base Excavation: | B35: =EXC!G5 -> 576 | D35: =EXC!D18 -> 2700
A36: Over 1,000 SQFT: | B36: =EXC!B17 -> 4 | C36: =EXC!C17 -> 0 | D36: =EXC!D17 -> 0
A37: =EXC!A20 -> Add'l 6" Depth: | B37: =EXC!B20 -> 90 | C37: =EXC!C20 -> 0 | D37: =EXC!D20 -> 0
A38: =EXC!A21 -> 6" RBB: | B38: =EXC!B21 -> 5 | C38: =EXC!C21 -> 0 | D38: =EXC!D21 -> 0
A39: =EXC!A22 -> 12" RBB: | B39: =EXC!B22 -> 6.5 | C39: =EXC!C22 -> 0 | D39: =EXC!D22 -> 0
A40: =EXC!A23 -> 18" RBB: | B40: =EXC!B23 -> 7.5 | C40: =EXC!C23 -> 0 | D40: =EXC!D23 -> 0
A41: =EXC!A24 -> 24" RBB: | B41: =EXC!B24 -> 8.5 | C41: =EXC!C24 -> 0 | D41: =EXC!D24 -> 0
A42: =EXC!A25 -> 30" RBB" | B42: =EXC!B25 -> 9 | C42: =EXC!C25 -> 0 | D42: =EXC!D25 -> 0
A43: =EXC!A26 -> 36" RBB: | B43: =EXC!B26 -> 10 | C43: =EXC!C26 -> 0 | D43: =EXC!D26 -> 0
A44: =EXC!A27 -> Base Spa: | B44: =EXC!B27 -> 200 | C44: =EXC!C27 -> 0 | D44: =EXC!D27 -> 0
A45: =EXC!A28 -> Raise Spa: | B45: =EXC!B28 -> 350 | C45: =EXC!C28 -> 0 | D45: =EXC!D28 -> 0
A46: =EXC!A29 -> Site Prep: | B46: =EXC!B29 -> 200 | C46: =EXC!C29 -> 0 | D46: =EXC!D29 -> 0
A47: =EXC!A30 -> Backfill: | B47: =EXC!B30 -> 600 | C47: =EXC!C30 -> 1 | D47: =EXC!D30 -> 600
A48: =EXC!A31 -> Gravel: | B48: =EXC!B31 -> 1 | C48: =EXC!C31 -> 2.75 | D48: =EXC!D31 -> 1584
A49: =EXC!A32 -> Dirt Haul: | B49: =EXC!B32 -> 18 | C49: =ROUNDUP(EXC!C32,0) -> 180 | D49: =ROUNDUP(EXC!D32,0) -> 3230
...

Sheet SUMMARY - REMODEL
A1: JOB COST SUMMARY
A3: CUSTOMER NAME: | B3: ='NEW POOL'!B3 -> Bishop
A5: PLANS & ENGINEERING TOTAL | D5: ='COST - REMODEL'!D9 -> 0
A7: LAYOUT TOTAL | D7: ='COST - REMODEL'!D16 -> 550
A9: PERMIT TOTAL | D9: ='COST - REMODEL'!D23 -> 0
A11: DEMO TOTAL | D11: ='COST - REMODEL'!D32 -> 3927
A13: EXCAVATION TOTAL: | D13: ='COST - REMODEL'!D54 -> 0
A15: PLUMBING TOTAL: | D15: ='COST - REMODEL'!D75 -> 0
A17: GAS TOTAL: | D17: ='COST - REMODEL'!D81 -> 0
A19: STEEL TOTAL: | D19: ='COST - REMODEL'!D108 -> 0
A21: ELECTRICAL TOTAL: | D21: ='COST - REMODEL'!D124 -> 0
A23: TILE LABOR TOTAL: | D23: ='COST - REMODEL'!D175 -> 1560
A25: TILE MATERIAL TOTAL: | D25: ='COST - REMODEL'!D177 -> 560
A27: COPING / DECKING LABOR TOTAL: | D27: ='COST - REMODEL'!D206 -> 0
A29: COPING / DECKING MATERIAL TOTAL: | D29: ='COST - REMODEL'!D208 -> 0
A31: STONE / ROCKWORK LABOR TOTAL: | D31: ='COST - REMODEL'!D227 -> 0
A33: STONE / ROCKWORK MATERIAL TOTAL: | D33: ='COST - REMODEL'!D229 -> 0
A35: DRAINAGE: | D35: ='COST - REMODEL'!D210 -> 0
A37: EQUIPMENT ORDERED TOTAL: | D37: ='COST - REMODEL'!D257 -> 1450.8344
A39: EQUIPMENT SET TOTAL: | D39: ='COST - REMODEL'!D266 -> 0
A41: CLEAN-UP TOTAL: | D41: ='COST - REMODEL'!D273 -> 350
A43: INTERIOR FINISH TOTAL: | D43: ='COST - REMODEL'!D286 -> 6271
A45: WATER TRUCK TOTAL: | D45: ='COST - REMODEL'!D292 -> 980
A47: START-UP / ORIENTATION TOTAL: | D47: ='COST - NEW'!D330 -> 1000
A49: =CUSTOM!A3 -> Parged Concrete | D49: ='COST - NEW'!D333 -> 0
A51: =CUSTOM!A5 -> Oversized coping | D51: ='COST - NEW'!D334 -> 824
A53: =CUSTOM!A7 -> handrail | D53: ='COST - NEW'!D335 -> 1028
A55: =CUSTOM!A9 -> No Custom Feature | D55: ='COST - NEW'!D336 -> 0
A57: =CUSTOM!A11 -> No Custom Feature | D57: ='COST - NEW'!D337 -> 0
A59: =CUSTOM!A13 -> No Custom Feature | D59: ='COST - NEW'!D338 -> 0
A61: =CUSTOM!A15 -> No Custom Feature | D61: ='COST - NEW'!D339 -> 0
A63: =CUSTOM!A17 -> No Custom Feature | D63: ='COST - NEW'!D340 -> 0
A65: TOTAL COST: | D65: =SUM(D5:D64) -> 18500.834

Sheet EQUIP
M1: MAY 2022 | P1: COST | Q1: RETAIL | R1: TAX
A2: 2020 SCP PRICING | H2: 0.08 | I2: 0.69 | N2: NP | O2: Remodel | P2: =P111*(1+R2) -> 8239 | Q2: =((S111*(1+R2))) -> 11684.4 | R2: 0.07
A3: UPDATED: | B3: 43922 | M3: Base White Goods: | N3: =SUM(N4:N10) -> 1046.1 | O3: =SUM(O4:O10) -> 216.6 | P3: See Bottom for Detail
M4: Skimmer | N4: 120 | O4: 0 | S4: Remodel Set: | T4: 250
M5: AutoFill | N5: 100 | O5: 0
M6: Layout Paint | N6: =10*1.06 -> 10.6 | O6: =10*1.06 -> 10.6
M7: Permit Box | N7: =25*1.06 -> 26.5 | O7: 0 | P7: Check Valve: | Q7: 65
M8: Valves | N8: =550*1.06 -> 583 | O8: 0
A9: Misc | M9: Gift Basket | N9: 100 | O9: 100
D10: 2015 | E10: 2017 | F10: 2018 | G10: 2019 | M10: Misc | N10: =100*1.06 -> 106 | O10: =100*1.06 -> 106
B11: Skimmer | C11: HAY-25-1559 | D11: 69.92 | E11: =D11*1.05 -> 73.416 | F11: =E11*1.05 -> 77.0868 | G11: =+F11*1.03 -> 79.399404 | H11: =G11*(1+$H$2) -> 85.751356 | I11: =H11/$I$2 -> 124.27733 | M11: Retail | N11: =N3/S13 -> 1494.4286 | O11: =O3/S13 -> 309.42857
M13: PUMPS | O13: Main Drain | P13: Valve | Q13: Remodel | R13: Rem Retail | S13: 0.7
M14: No Auxiliary Pump | N14: 0 | O14: 0 | Q14: =SUM(N14:P14) -> 0 | R14: 0 | S14: =SUM(N14:Q14) -> 0 | U14: No Auxiliary Pump Selected
M15: Jandy 1.65HP Variable Pump | N15: 1153.6 | O15: 290 | P15: 90 | Q15: =SUM(N15:P15)*1.1 -> 1686.96 | R15: =((N15+P15)/$S$13)*1.2 -> 2131.8857 | S15: =CEILING(Q15/$S$13,10)-100 -> 2310 | T15: =S15-S16 -> -230
M16: Jandy 1.85HP Variable Pump | N16: 1236 | O16: 290 | P16: =P15 -> 90 | Q16: =SUM(N16:P16)*1.1 -> 1777.6 | R16: =((N16+P16)/$S$13)*1.2 -> 2273.1429 | S16: =CEILING(Q16/$S$13,10) -> 2540 | T16: INCLUDED
M17: Jandy 2.7HP Variable Pump | N17: 1596.5 | O17: 290 | P17: =P16 -> 90 | Q17: =SUM(N17:P17)*1.1 -> 2174.15 | R17: =((N17+P17)/$S$13)*1.2 -> 2891.1429 | S17: =CEILING(Q17/$S$13,10) -> 3110 | T17: =S17-S16 -> 570
B18: Paramount Venturi Skimmer | D18: 90 | E18: =D18*1.05 -> 94.5 | F18: 125 | G18: =+F18*1.03 -> 128.75 | H18: =G18*(1+$H$2) -> 139.05 | I18: =H18/$I$2 -> 201.52174 | M18: Jandy 1.0HP Single Speed Pump | N18: 824 | O18: =O17 -> 290 | P18: =P16 -> 90 | Q18: =SUM(N18:P18)*1.1 -> 1324.4 | R18: =((N18+P18)/$S$13)*1.2 -> 1566.8571 | S18: =CEILING(Q18/$S$13,10) -> 1900
M19: Jandy 2.0HP Single Speed Pump | N19: 927 | O19: =O18 -> 290 | P19: =P16 -> 90 | Q19: =SUM(N19:P19)*1.1 -> 1437.7 | R19: =((N19+P19)/$S$13)*1.2 -> 1743.4286 | S19: =CEILING(Q19/$S$13,10) -> 2060
B21: Vac Lock for Vac Line | C21: HAY-20-518 | D21: 20.13 | E21: =D21*1.05 -> 21.1365 | F21: =E21*1.04 -> 21.98196 | G21: =+F21*1.03 -> 22.641419 | H21: =G21*(1+$H$2) -> 24.452732 | I21: =H21/$I$2 -> 35.438742 | M21: FILTERS | O21: NP Upgrade | P21: Valve Remodel | Q21: Rem Cost | R21: Rem Retail | S21: 0.7
M22: No Filter | N22: 0 | O22: 0 | Q22: 0 | S22: =N22/$S$21 -> 0
M23: 200 SQFT Cartridge Filter | N23: 772.5 | O23: =S23-S24 -> -515 | P23: =P15 -> 90 | Q23: =((N23+P23))*1.1 -> 948.75 | R23: =Q23/$S$21 -> 1355.3571 | S23: =N23/$S$21 -> 1103.5714
B24: Polaris 360 - Standard | C24: POL-20-520 | D24: 439.87 | E24: =D24*1.05 -> 461.8635 | F24: =E24*1.04 -> 480.33804 | G24: =+F24*1.03 -> 494.74818 | H24: =G24*(1+$H$2) -> 534.32804 | I24: =H24/$I$2 -> 774.38846 | M24: 340 SQFT Cartridge Filter | N24: 1133 | O24: INCLUDED | P24: =P23 -> 90 | Q24: =((N24+P24))*1.1 -> 1345.3 | R24: =Q24/$S$21 -> 1921.8571 | S24: =N24/$S$21 -> 1618.5714 | U24: http://www.jandy.com/en/products/filters/cv
B25: Polaris 360 - Black | C25: POL-20-531 | D25: 535.8 | E25: =D25*1.05 -> 562.59 | F25: =E25*1.04 -> 585.0936 | G25: =+F25*1.03 -> 602.64641 | H25: =G25*(1+$H$2) -> 650.85812 | I25: =H25/$I$2 -> 943.27264 | M25: 460 SQFT Cartridge Filter | N25: 1174.2 | O25: =CEILING((N25-$N$24)*1.7,20) -> 80 | P25: =P24 -> 90 | Q25: =((N25+P25))*1.1 -> 1390.62 | R25: =Q25/$S$21 -> 1986.6 | S25: =N25/$S$21 -> 1677.4286 | U25: http://www.jandy.com/en/products/filters/cv
B26: Polaris 280 w/ Booster | E26: =547.7+251.35 -> 799.05 | F26: =580+250 -> 830 | G26: =+F26*1.03 -> 854.9 | H26: =G26*(1+$H$2) -> 923.292 | I26: =H26/$I$2 -> 1338.1043 | M26: 580 SQFT Cartridge Filter | N26: 1493.5 | O26: =CEILING((N26-$N$24)*1.7,20) -> 620 | P26: =P25 -> 90 | Q26: =((N26+P26))*1.1 -> 1741.85 | R26: =Q26/$S$21 -> 2488.3571 | S26: =N26/$S$21 -> 2133.5714 | U26: http://www.jandy.com/en/products/filters/cv
B27: Pool rx | D27: 69.41 | E27: =D27*1.05 -> 72.8805 | F27: =E27*1.04 -> 75.79572 | G27: =+F27*1.03 -> 78.069592 | H27: =G27*(1+$H$2) -> 84.315159 | I27: =H27/$I$2 -> 122.19588 | M27: 4.9 SQFT Sand Filter | N27: 780.64 | O27: INCLUDED | P27: =P26 -> 90 | Q27: =((N27+P27))*1.1 -> 957.704 | R27: =Q27/$S$21 -> 1368.1486 | S27: =N27/$S$21 -> 1115.2 | U27: http://www.jandy.com/en/products/filters/js
